<?xml version="1.0" ?>
<!-- Generated using onshape-to-robot -->
<!-- OnShape https://cad.onshape.com/documents/583eecc93f1fd4583e084f73/w/778291f6b7322eff9511ad40/e/3a18360e1873d25fc3c36e80 -->

<robot name="awc_robot" xmlns:xacro="http://www.ros.org/wiki/xacro">
    <xacro:include filename="$(find robot_description)/urdf/robot_gazebo.xacro"/>

    <!-- Link part_1 -->
    <link name="base_link">
        <inertial>
            <origin xyz="-0.209543 -0.140978 0.819711" rpy="0 0 0"/>
            <mass value="122.64"/>
            <inertia ixx="6.3733" ixy="0.000452647" ixz="-3.70783e-05" iyy="4.73591" iyz="-1.64746" izz="5.57395"/>
        </inertial>
        <!-- Part part_1 -->
        <visual>
            <origin xyz="-0.189996 0.0621512 0.638136" rpy="-0.0872665 -2.76507e-17 -3.66353e-16"/>
            <geometry>
                <mesh filename="package://robot_description/meshes/part_1.stl"/>
            </geometry>
            <material name="part_1_material">
                <color rgba="0.513725 0.737255 0.407843 1.0"/>
            </material>
        </visual>
        <collision>
            <origin xyz="-0.189996 0.0621512 0.638136" rpy="-0.0872665 -2.76507e-17 -3.66353e-16"/>
            <geometry>
                <mesh filename="package://robot_description/meshes/part_1.stl"/>
            </geometry>
        </collision>
    </link>
    <!-- Link part_1_2 -->
    <link name="part_1_2">
        <inertial>
            <origin xyz="-1.44802e-54 6.55416e-18 -0.0223" rpy="0 0 0"/>
            <mass value="1.00876"/>
            <inertia ixx="0.00182587" ixy="0" ixz="-1.14476e-57" iyy="0.00182587" iyz="9.76022e-54" izz="0.0033173"/>
        </inertial>
        <!-- Part part_1_2 -->
        <visual>
            <origin xyz="0 0 -0.0446" rpy="-1.5708 -9.06351e-55 0"/>
            <geometry>
                <mesh filename="package://robot_description/meshes/part_1.2.stl"/>
            </geometry>
            <material name="part_1_2_material">
                <color rgba="0.301961 0.301961 0.301961 1.0"/>
            </material>
        </visual>
        <collision>
            <origin xyz="0 0 -0.0446" rpy="-1.5708 -9.06351e-55 0"/>
            <geometry>
                <mesh filename="package://robot_description/meshes/part_1.2.stl"/>
            </geometry>
        </collision>
    </link>
    <!-- Joint from part_1 to part_1_2 -->
    <joint name="right_wheel" type="continuous">
        <origin xyz="-0.480688 -0.0711889 0.605633" rpy="-1.5708 3.3994e-20 1.5708"/>
        <parent link="base_link"/>
        <child link="part_1_2"/>
        <axis xyz="0 0 1"/>
        <limit effort="10" velocity="6"/>
        <joint_properties friction="{'max_effort': 10.0, 'max_velocity': 6.0, 'friction': 0.0}"/>
    </joint>
    <!-- Link part_1_3 -->
    <link name="part_1_3">
        <inertial>
            <origin xyz="-1.11022e-16 6.55416e-18 -0.0223" rpy="0 0 0"/>
            <mass value="1.00876"/>
            <inertia ixx="0.00182587" ixy="2.01598e-66" ixz="2.08567e-34" iyy="0.00182587" iyz="6.33944e-35" izz="0.0033173"/>
        </inertial>
        <!-- Part part_1_3 -->
        <visual>
            <origin xyz="-1.11022e-16 0 -0.0446" rpy="-1.5708 -2.46519e-32 0"/>
            <geometry>
                <mesh filename="package://robot_description/meshes/part_1.2.stl"/>
            </geometry>
            <material name="part_1_3_material">
                <color rgba="0.301961 0.301961 0.301961 1.0"/>
            </material>
        </visual>
        <collision>
            <origin xyz="-1.11022e-16 0 -0.0446" rpy="-1.5708 -2.46519e-32 0"/>
            <geometry>
                <mesh filename="package://robot_description/meshes/part_1.2.stl"/>
            </geometry>
        </collision>
    </link>
    <!-- Joint from part_1 to part_1_3 -->
    <joint name="left_wheel" type="continuous">
        <origin xyz="0.0616039 -0.0708403 0.609618" rpy="1.5708 -1.30234 1.5708"/>
        <parent link="base_link"/>
        <child link="part_1_3"/>
        <axis xyz="0 0 1"/>
        <limit effort="10" velocity="6"/>
        <joint_properties friction="{'max_effort': 10.0, 'max_velocity': 6.0, 'friction': 0.0}"/>
    </joint>
</robot>
